<sdf version='1.7'>
  <world name='maze_world'>
    <light name='sun' type='directional'>
      <cast_shadows>1</cast_shadows>
      <pose>0 0 10 0 -0 0</pose>
      <diffuse>0.8 0.8 0.8 1</diffuse>
      <specular>0.2 0.2 0.2 1</specular>
      <attenuation>
        <range>1000</range>
        <constant>0.9</constant>
        <linear>0.01</linear>
        <quadratic>0.001</quadratic>
      </attenuation>
      <direction>-0.5 0.1 -0.9</direction>
      <spot>
        <inner_angle>0</inner_angle>
        <outer_angle>0</outer_angle>
        <falloff>0</falloff>
      </spot>
    </light>
    <model name='ground_plane'>
      <static>1</static>
      <link name='link'>
        <collision name='collision'>
          <geometry>
            <plane>
              <normal>0 0 1</normal>
              <size>100 100</size>
            </plane>
          </geometry>
          <surface>
            <friction>
              <ode>
                <mu>100</mu>
                <mu2>50</mu2>
              </ode>
              <torsional>
                <ode/>
              </torsional>
            </friction>
            <contact>
              <ode/>
            </contact>
            <bounce/>
          </surface>
          <max_contacts>10</max_contacts>
        </collision>
        <visual name='visual'>
          <cast_shadows>0</cast_shadows>
          <geometry>
            <plane>
              <normal>0 0 1</normal>
              <size>100 100</size>
            </plane>
          </geometry>
          <material>
            <script>
              <uri>file://media/materials/scripts/gazebo.material</uri>
              <name>Gazebo/Grey</name>
            </script>
          </material>
        </visual>
        <self_collide>0</self_collide>
        <enable_wind>0</enable_wind>
        <kinematic>0</kinematic>
      </link>
    </model>
    <model name='maze'>
      <pose>-0.078283 0.098984 0 0 -0 0</pose>
      <link name='Wall_0'>
        <collision name='Wall_0_Collision'>
          <geometry>
            <box>
              <size>20 0.15 2.5</size>
            </box>
          </geometry>
          <pose>0 0 1.25 0 -0 0</pose>
          <max_contacts>10</max_contacts>
          <surface>
            <contact>
              <ode/>
            </contact>
            <bounce/>
            <friction>
              <torsional>
                <ode/>
              </torsional>
              <ode/>
            </friction>
          </surface>
        </collision>
        <visual name='Wall_0_Visual'>
          <pose>0 0 1.25 0 -0 0</pose>
          <geometry>
            <box>
              <size>20 0.15 2.5</size>
            </box>
          </geometry>
          <material>
            <script>
              <uri>file://media/materials/scripts/gazebo.material</uri>
              <name>Gazebo/Grey</name>
            </script>
            <ambient>1 1 1 1</ambient>
          </material>
        </visual>
        <pose>0.030536 9.925 0 0 -0 0</pose>
        <self_collide>0</self_collide>
        <enable_wind>0</enable_wind>
        <kinematic>0</kinematic>
      </link>
      <link name='Wall_1'>
        <collision name='Wall_1_Collision'>
          <geometry>
            <box>
              <size>20 0.15 2.5</size>
            </box>
          </geometry>
          <pose>0 0 1.25 0 -0 0</pose>
          <max_contacts>10</max_contacts>
          <surface>
            <contact>
              <ode/>
            </contact>
            <bounce/>
            <friction>
              <torsional>
                <ode/>
              </torsional>
              <ode/>
            </friction>
          </surface>
        </collision>
        <visual name='Wall_1_Visual'>
          <pose>0 0 1.25 0 -0 0</pose>
          <geometry>
            <box>
              <size>20 0.15 2.5</size>
            </box>
          </geometry>
          <material>
            <script>
              <uri>file://media/materials/scripts/gazebo.material</uri>
              <name>Gazebo/Grey</name>
            </script>
            <ambient>1 1 1 1</ambient>
          </material>
        </visual>
        <pose>9.95554 0 0 0 0 -1.5708</pose>
        <self_collide>0</self_collide>
        <enable_wind>0</enable_wind>
        <kinematic>0</kinematic>
      </link>
      <link name='Wall_2'>
        <collision name='Wall_2_Collision'>
          <geometry>
            <box>
              <size>20 0.15 2.5</size>
            </box>
          </geometry>
          <pose>0 0 1.25 0 -0 0</pose>
          <max_contacts>10</max_contacts>
          <surface>
            <contact>
              <ode/>
            </contact>
            <bounce/>
            <friction>
              <torsional>
                <ode/>
              </torsional>
              <ode/>
            </friction>
          </surface>
        </collision>
        <visual name='Wall_2_Visual'>
          <pose>0 0 1.25 0 -0 0</pose>
          <geometry>
            <box>
              <size>20 0.15 2.5</size>
            </box>
          </geometry>
          <material>
            <script>
              <uri>file://media/materials/scripts/gazebo.material</uri>
              <name>Gazebo/Grey</name>
            </script>
            <ambient>1 1 1 1</ambient>
          </material>
        </visual>
        <pose>0.030536 -9.925 0 0 -0 3.14159</pose>
        <self_collide>0</self_collide>
        <enable_wind>0</enable_wind>
        <kinematic>0</kinematic>
      </link>
      <link name='Wall_24'>
        <collision name='Wall_24_Collision'>
          <geometry>
            <box>
              <size>1.5 0.15 2.5</size>
            </box>
          </geometry>
          <pose>0 0 1.25 0 -0 0</pose>
          <max_contacts>10</max_contacts>
          <surface>
            <contact>
              <ode/>
            </contact>
            <bounce/>
            <friction>
              <torsional>
                <ode/>
              </torsional>
              <ode/>
            </friction>
          </surface>
        </collision>
        <visual name='Wall_24_Visual'>
          <pose>0 0 1.25 0 -0 0</pose>
          <geometry>
            <box>
              <size>1.5 0.15 2.5</size>
            </box>
          </geometry>
          <material>
            <script>
              <uri>file://media/materials/scripts/gazebo.material</uri>
              <name>Gazebo/Grey</name>
            </script>
            <ambient>1 1 1 1</ambient>
          </material>
        </visual>
        <pose>5.35089 3.21906 0 0 -0 3.14159</pose>
        <self_collide>0</self_collide>
        <enable_wind>0</enable_wind>
        <kinematic>0</kinematic>
      </link>
      <link name='Wall_25'>
        <collision name='Wall_25_Collision'>
          <geometry>
            <box>
              <size>5.25 0.15 2.5</size>
            </box>
          </geometry>
          <pose>0 0 1.25 0 -0 0</pose>
          <max_contacts>10</max_contacts>
          <surface>
            <contact>
              <ode/>
            </contact>
            <bounce/>
            <friction>
              <torsional>
                <ode/>
              </torsional>
              <ode/>
            </friction>
          </surface>
        </collision>
        <visual name='Wall_25_Visual'>
          <pose>0 0 1.25 0 -0 0</pose>
          <geometry>
            <box>
              <size>5.25 0.15 2.5</size>
            </box>
          </geometry>
          <material>
            <script>
              <uri>file://media/materials/scripts/gazebo.material</uri>
              <name>Gazebo/Grey</name>
            </script>
            <ambient>1 1 1 1</ambient>
          </material>
        </visual>
        <pose>4.67589 5.76906 0 0 -0 1.5708</pose>
        <self_collide>0</self_collide>
        <enable_wind>0</enable_wind>
        <kinematic>0</kinematic>
      </link>
      <link name='Wall_27'>
        <collision name='Wall_27_Collision'>
          <geometry>
            <box>
              <size>5.5 0.15 2.5</size>
            </box>
          </geometry>
          <pose>0 0 1.25 0 -0 0</pose>
          <max_contacts>10</max_contacts>
          <surface>
            <contact>
              <ode/>
            </contact>
            <bounce/>
            <friction>
              <torsional>
                <ode/>
              </torsional>
              <ode/>
            </friction>
          </surface>
        </collision>
        <visual name='Wall_27_Visual'>
          <pose>0 0 1.25 0 -0 0</pose>
          <geometry>
            <box>
              <size>5.5 0.15 2.5</size>
            </box>
          </geometry>
          <material>
            <script>
              <uri>file://media/materials/scripts/gazebo.material</uri>
              <name>Gazebo/Grey</name>
            </script>
            <ambient>1 1 1 1</ambient>
          </material>
        </visual>
        <pose>7.10914 4.73454 0 0 0 -1.5708</pose>
        <self_collide>0</self_collide>
        <enable_wind>0</enable_wind>
        <kinematic>0</kinematic>
      </link>
      <link name='Wall_28'>
        <collision name='Wall_28_Collision'>
          <geometry>
            <box>
              <size>3 0.15 2.5</size>
            </box>
          </geometry>
          <pose>0 0 1.25 0 -0 0</pose>
          <max_contacts>10</max_contacts>
          <surface>
            <contact>
              <ode/>
            </contact>
            <bounce/>
            <friction>
              <torsional>
                <ode/>
              </torsional>
              <ode/>
            </friction>
          </surface>
        </collision>
        <visual name='Wall_28_Visual'>
          <pose>0 0 1.25 0 -0 0</pose>
          <geometry>
            <box>
              <size>3 0.15 2.5</size>
            </box>
          </geometry>
          <material>
            <script>
              <uri>file://media/materials/scripts/gazebo.material</uri>
              <name>Gazebo/Grey</name>
            </script>
            <ambient>1 1 1 1</ambient>
          </material>
        </visual>
        <pose>8.53414 2.05954 0 0 -0 0</pose>
        <self_collide>0</self_collide>
        <enable_wind>0</enable_wind>
        <kinematic>0</kinematic>
      </link>
      <link name='Wall_3'>
        <collision name='Wall_3_Collision'>
          <geometry>
            <box>
              <size>20 0.15 2.5</size>
            </box>
          </geometry>
          <pose>0 0 1.25 0 -0 0</pose>
          <max_contacts>10</max_contacts>
          <surface>
            <contact>
              <ode/>
            </contact>
            <bounce/>
            <friction>
              <torsional>
                <ode/>
              </torsional>
              <ode/>
            </friction>
          </surface>
        </collision>
        <visual name='Wall_3_Visual'>
          <pose>0 0 1.25 0 -0 0</pose>
          <geometry>
            <box>
              <size>20 0.15 2.5</size>
            </box>
          </geometry>
          <material>
            <script>
              <uri>file://media/materials/scripts/gazebo.material</uri>
              <name>Gazebo/Grey</name>
            </script>
            <ambient>1 1 1 1</ambient>
          </material>
        </visual>
        <pose>-9.89446 0 0 0 -0 1.5708</pose>
        <self_collide>0</self_collide>
        <enable_wind>0</enable_wind>
        <kinematic>0</kinematic>
      </link>
      <link name='Wall_30'>
        <collision name='Wall_30_Collision'>
          <geometry>
            <box>
              <size>5.5 0.15 2.5</size>
            </box>
          </geometry>
          <pose>0 0 1.25 0 -0 0</pose>
          <max_contacts>10</max_contacts>
          <surface>
            <contact>
              <ode/>
            </contact>
            <bounce/>
            <friction>
              <torsional>
                <ode/>
              </torsional>
              <ode/>
            </friction>
          </surface>
        </collision>
        <visual name='Wall_30_Visual'>
          <pose>0 0 1.25 0 -0 0</pose>
          <geometry>
            <box>
              <size>5.5 0.15 2.5</size>
            </box>
          </geometry>
          <material>
            <script>
              <uri>file://media/materials/scripts/gazebo.material</uri>
              <name>Gazebo/Grey</name>
            </script>
            <ambient>1 1 1 1</ambient>
          </material>
        </visual>
        <pose>-4.35914 -2.82889 0 0 0 -1.5708</pose>
        <self_collide>0</self_collide>
        <enable_wind>0</enable_wind>
        <kinematic>0</kinematic>
      </link>
      <link name='Wall_31'>
        <collision name='Wall_31_Collision'>
          <geometry>
            <box>
              <size>5.75 0.15 2.5</size>
            </box>
          </geometry>
          <pose>0 0 1.25 0 -0 0</pose>
          <max_contacts>10</max_contacts>
          <surface>
            <contact>
              <ode/>
            </contact>
            <bounce/>
            <friction>
              <torsional>
                <ode/>
              </torsional>
              <ode/>
            </friction>
          </surface>
        </collision>
        <visual name='Wall_31_Visual'>
          <pose>0 0 1.25 0 -0 0</pose>
          <geometry>
            <box>
              <size>5.75 0.15 2.5</size>
            </box>
          </geometry>
          <material>
            <script>
              <uri>file://media/materials/scripts/gazebo.material</uri>
              <name>Gazebo/Grey</name>
            </script>
            <ambient>1 1 1 1</ambient>
          </material>
        </visual>
        <pose>-7.15914 -5.50389 0 0 -0 3.14159</pose>
        <self_collide>0</self_collide>
        <enable_wind>0</enable_wind>
        <kinematic>0</kinematic>
      </link>
      <link name='Wall_5'>
        <collision name='Wall_5_Collision'>
          <geometry>
            <box>
              <size>16 0.15 2.5</size>
            </box>
          </geometry>
          <pose>0 0 1.25 0 -0 0</pose>
          <max_contacts>10</max_contacts>
          <surface>
            <contact>
              <ode/>
            </contact>
            <bounce/>
            <friction>
              <torsional>
                <ode/>
              </torsional>
              <ode/>
            </friction>
          </surface>
        </collision>
        <visual name='Wall_5_Visual'>
          <pose>0 0 1.25 0 -0 0</pose>
          <geometry>
            <box>
              <size>16 0.15 2.5</size>
            </box>
          </geometry>
          <material>
            <script>
              <uri>file://media/materials/scripts/gazebo.material</uri>
              <name>Gazebo/Grey</name>
            </script>
            <ambient>1 1 1 1</ambient>
          </material>
        </visual>
        <pose>-1.89911 1.86906 0 0 -0 0</pose>
        <self_collide>0</self_collide>
        <enable_wind>0</enable_wind>
        <kinematic>0</kinematic>
      </link>
      <link name='Wall_6'>
        <collision name='Wall_6_Collision'>
          <geometry>
            <box>
              <size>1.5 0.15 2.5</size>
            </box>
          </geometry>
          <pose>0 0 1.25 0 -0 0</pose>
          <max_contacts>10</max_contacts>
          <surface>
            <contact>
              <ode/>
            </contact>
            <bounce/>
            <friction>
              <torsional>
                <ode/>
              </torsional>
              <ode/>
            </friction>
          </surface>
        </collision>
        <visual name='Wall_6_Visual'>
          <pose>0 0 1.25 0 -0 0</pose>
          <geometry>
            <box>
              <size>1.5 0.15 2.5</size>
            </box>
          </geometry>
          <material>
            <script>
              <uri>file://media/materials/scripts/gazebo.material</uri>
              <name>Gazebo/Grey</name>
            </script>
            <ambient>1 1 1 1</ambient>
          </material>
        </visual>
        <pose>6.02589 2.54406 0 0 -0 1.5708</pose>
        <self_collide>0</self_collide>
        <enable_wind>0</enable_wind>
        <kinematic>0</kinematic>
      </link>
      <link name='Wall_8'>
        <collision name='Wall_8_Collision'>
          <geometry>
            <box>
              <size>0.15 0.15 2.5</size>
            </box>
          </geometry>
          <pose>0 0 1.25 0 -0 0</pose>
          <max_contacts>10</max_contacts>
          <surface>
            <contact>
              <ode/>
            </contact>
            <bounce/>
            <friction>
              <torsional>
                <ode/>
              </torsional>
              <ode/>
            </friction>
          </surface>
        </collision>
        <visual name='Wall_8_Visual'>
          <pose>0 0 1.25 0 -0 0</pose>
          <geometry>
            <box>
              <size>0.15 0.15 2.5</size>
            </box>
          </geometry>
          <material>
            <script>
              <uri>file://media/materials/scripts/gazebo.material</uri>
              <name>Gazebo/Grey</name>
            </script>
            <ambient>1 1 1 1</ambient>
          </material>
        </visual>
        <pose>6.02589 3.21906 0 0 -0 0</pose>
        <self_collide>0</self_collide>
        <enable_wind>0</enable_wind>
        <kinematic>0</kinematic>
      </link>
      <static>1</static>
    </model>
    <gravity>0 0 -9.8</gravity>
    <magnetic_field>6e-06 2.3e-05 -4.2e-05</magnetic_field>
    <atmosphere type='adiabatic'/>
    <physics type='ode'>
      <max_step_size>0.001</max_step_size>
      <real_time_factor>1</real_time_factor>
      <real_time_update_rate>1000</real_time_update_rate>
    </physics>
    <scene>
      <ambient>0.4 0.4 0.4 1</ambient>
      <background>0.7 0.7 0.7 1</background>
      <shadows>1</shadows>
    </scene>
    <audio>
      <device>default</device>
    </audio>
    <wind/>
    <spherical_coordinates>
      <surface_model>EARTH_WGS84</surface_model>
      <latitude_deg>0</latitude_deg>
      <longitude_deg>0</longitude_deg>
      <elevation>0</elevation>
      <heading_deg>0</heading_deg>
    </spherical_coordinates>
    <model name='mir_robot'>
      <link name='base_footprint'>
        <inertial>
          <pose>-0.032079 0 0.209055 0 -0 0</pose>
          <mass>164.71</mass>
          <inertia>
            <ixx>2.80057</ixx>
            <ixy>-0.261272</ixy>
            <ixz>-0.312894</ixz>
            <iyy>5.29191</iyy>
            <iyz>0</iyz>
            <izz>5.25879</izz>
          </inertia>
        </inertial>
        <collision name='base_footprint_fixed_joint_lump__base_link_collision'>
          <pose>-0.004485 0 0 0 -0 0</pose>
          <geometry>
            <mesh>
              <scale>1 1 1</scale>
              <uri>model://mir_description/meshes/collision/mir_250_base.stl</uri>
            </mesh>
          </geometry>
          <surface>
            <contact>
              <ode/>
            </contact>
            <friction>
              <ode/>
              <torsional>
                <ode/>
              </torsional>
            </friction>
            <bounce/>
          </surface>
          <max_contacts>10</max_contacts>
        </collision>
        <collision name='base_footprint_fixed_joint_lump__back_laser_link_collision_1'>
          <pose>-0.3164 -0.2064 0.1914 3.14159 -0 -2.35619</pose>
          <geometry>
            <mesh>
              <scale>1 1 1</scale>
              <uri>model://mir_description/meshes/visual/sick_lms-100.stl</uri>
            </mesh>
          </geometry>
          <surface>
            <contact>
              <ode/>
            </contact>
            <friction>
              <ode/>
              <torsional>
                <ode/>
              </torsional>
            </friction>
            <bounce/>
          </surface>
          <max_contacts>10</max_contacts>
        </collision>
        <collision name='base_footprint_fixed_joint_lump__front_laser_link_collision_2'>
          <pose>0.3164 0.2064 0.1914 3.14159 -0 0.785398</pose>
          <geometry>
            <mesh>
              <scale>1 1 1</scale>
              <uri>model://mir_description/meshes/visual/sick_lms-100.stl</uri>
            </mesh>
          </geometry>
          <surface>
            <contact>
              <ode/>
            </contact>
            <friction>
              <ode/>
              <torsional>
                <ode/>
              </torsional>
            </friction>
            <bounce/>
          </surface>
          <max_contacts>10</max_contacts>
        </collision>
        <collision name='base_footprint_fixed_joint_lump__power_unit_collision_3'>
          <pose>0 0 0.545 0 -0 0</pose>
          <geometry>
            <box>
              <size>0.73 0.56 0.49</size>
            </box>
          </geometry>
          <max_contacts>10</max_contacts>
          <surface>
            <contact>
              <ode/>
            </contact>
            <bounce/>
            <friction>
              <torsional>
                <ode/>
              </torsional>
              <ode/>
            </friction>
          </surface>
        </collision>
        <collision name='base_footprint_fixed_joint_lump__ur_base_link_inertia_collision_4'>
          <pose>0.135 0 0.79 0 -0 1.5708</pose>
          <geometry>
            <mesh>
              <scale>1 1 1</scale>
              <uri>file:///media/typlosion/shadow/work/ROS/ros_ws/install/ur_description/share/ur_description/meshes/ur5e/collision/base.stl</uri>
            </mesh>
          </geometry>
          <max_contacts>10</max_contacts>
          <surface>
            <contact>
              <ode/>
            </contact>
            <bounce/>
            <friction>
              <torsional>
                <ode/>
              </torsional>
              <ode/>
            </friction>
          </surface>
        </collision>
        <visual name='base_footprint_fixed_joint_lump__base_link_visual'>
          <pose>-0.004485 0 0 0 -0 0</pose>
          <geometry>
            <mesh>
              <scale>1 1 1</scale>
              <uri>model://mir_description/meshes/visual/mir_250_base.stl</uri>
            </mesh>
          </geometry>
          <material>
            <script>
              <name>Gazebo/Grey</name>
              <uri>file://media/materials/scripts/gazebo.material</uri>
            </script>
          </material>
        </visual>
        <visual name='base_footprint_fixed_joint_lump__back_laser_link_visual_1'>
          <pose>-0.3164 -0.2064 0.1914 3.14159 -0 -2.35619</pose>
          <geometry>
            <mesh>
              <scale>1 1 1</scale>
              <uri>model://mir_description/meshes/visual/sick_lms-100.stl</uri>
            </mesh>
          </geometry>
          <material>
            <script>
              <name>Gazebo/FlatBlack</name>
              <uri>file://media/materials/scripts/gazebo.material</uri>
            </script>
          </material>
        </visual>
        <visual name='base_footprint_fixed_joint_lump__front_laser_link_visual_2'>
          <pose>0.3164 0.2064 0.1914 3.14159 -0 0.785398</pose>
          <geometry>
            <mesh>
              <scale>1 1 1</scale>
              <uri>model://mir_description/meshes/visual/sick_lms-100.stl</uri>
            </mesh>
          </geometry>
          <material>
            <script>
              <name>Gazebo/FlatBlack</name>
              <uri>file://media/materials/scripts/gazebo.material</uri>
            </script>
          </material>
        </visual>
        <visual name='base_footprint_fixed_joint_lump__power_unit_visual_3'>
          <pose>0 0 0.545 0 -0 0</pose>
          <geometry>
            <box>
              <size>0.73 0.56 0.49</size>
            </box>
          </geometry>
        </visual>
        <visual name='base_footprint_fixed_joint_lump__ur_base_link_inertia_visual_4'>
          <pose>0.135 0 0.79 0 -0 1.5708</pose>
          <geometry>
            <mesh>
              <scale>1 1 1</scale>
              <uri>file:///media/typlosion/shadow/work/ROS/ros_ws/install/ur_description/share/ur_description/meshes/ur5e/visual/base.dae</uri>
            </mesh>
          </geometry>
        </visual>
        <sensor name='back_laser_link' type='ray'>
          <visualize>0</visualize>
          <update_rate>12.5</update_rate>
          <ray>
            <scan>
              <horizontal>
                <samples>541</samples>
                <resolution>1</resolution>
                <min_angle>-2.09438</min_angle>
                <max_angle>2.09438</max_angle>
              </horizontal>
              <vertical>
                <samples>1</samples>
                <min_angle>0</min_angle>
                <max_angle>0</max_angle>
              </vertical>
            </scan>
            <range>
              <min>0.05</min>
              <max>29</max>
              <resolution>0.01</resolution>
            </range>
            <noise>
              <type>gaussian</type>
              <mean>0</mean>
              <stddev>0.01</stddev>
            </noise>
          </ray>
          <plugin name='gazebo_ros_back_laser_link_controller' filename='libgazebo_ros_ray_sensor.so'>
            <ros>
              <remapping>~/out:=b_scan</remapping>
            </ros>
            <output_type>sensor_msgs/LaserScan</output_type>
            <frame_name>back_laser_link</frame_name>
          </plugin>
          <pose>-0.3164 -0.2064 0.1914 0 0 -2.35619</pose>
        </sensor>
        <sensor name='front_laser_link' type='ray'>
          <visualize>0</visualize>
          <update_rate>12.5</update_rate>
          <ray>
            <scan>
              <horizontal>
                <samples>541</samples>
                <resolution>1</resolution>
                <min_angle>-2.09438</min_angle>
                <max_angle>2.09438</max_angle>
              </horizontal>
              <vertical>
                <samples>1</samples>
                <min_angle>0</min_angle>
                <max_angle>0</max_angle>
              </vertical>
            </scan>
            <range>
              <min>0.05</min>
              <max>29</max>
              <resolution>0.01</resolution>
            </range>
            <noise>
              <type>gaussian</type>
              <mean>0</mean>
              <stddev>0.01</stddev>
            </noise>
          </ray>
          <plugin name='gazebo_ros_front_laser_link_controller' filename='libgazebo_ros_ray_sensor.so'>
            <ros>
              <remapping>~/out:=f_scan</remapping>
            </ros>
            <output_type>sensor_msgs/LaserScan</output_type>
            <frame_name>front_laser_link</frame_name>
          </plugin>
          <pose>0.3164 0.2064 0.1914 0 -0 0.785398</pose>
        </sensor>
        <gravity>1</gravity>
        <sensor name='imu_sensor' type='imu'>
          <always_on>1</always_on>
          <update_rate>50</update_rate>
          <visualize>1</visualize>
          <imu>
            <angular_velocity>
              <x>
                <noise type='gaussian'>
                  <mean>0</mean>
                  <stddev>0.00017</stddev>
                  <bias_mean>7.5e-06</bias_mean>
                  <bias_stddev>8e-07</bias_stddev>
                </noise>
              </x>
              <y>
                <noise type='gaussian'>
                  <mean>0</mean>
                  <stddev>0.00017</stddev>
                  <bias_mean>7.5e-06</bias_mean>
                  <bias_stddev>8e-07</bias_stddev>
                </noise>
              </y>
              <z>
                <noise type='gaussian'>
                  <mean>0</mean>
                  <stddev>0.00017</stddev>
                  <bias_mean>7.5e-06</bias_mean>
                  <bias_stddev>8e-07</bias_stddev>
                </noise>
              </z>
            </angular_velocity>
            <linear_acceleration>
              <x>
                <noise type='gaussian'>
                  <mean>0</mean>
                  <stddev>0.00017</stddev>
                  <bias_mean>0.1</bias_mean>
                  <bias_stddev>0.001</bias_stddev>
                </noise>
              </x>
              <y>
                <noise type='gaussian'>
                  <mean>0</mean>
                  <stddev>0.00017</stddev>
                  <bias_mean>0.1</bias_mean>
                  <bias_stddev>0.001</bias_stddev>
                </noise>
              </y>
              <z>
                <noise type='gaussian'>
                  <mean>0</mean>
                  <stddev>0.00017</stddev>
                  <bias_mean>0.1</bias_mean>
                  <bias_stddev>0.001</bias_stddev>
                </noise>
              </z>
            </linear_acceleration>
          </imu>
          <plugin name='imu_plugin' filename='libgazebo_ros_imu_sensor.so'>
            <initial_orientation_as_reference>0</initial_orientation_as_reference>
            <ros>
              <namespace>imu_data</namespace>
              <remapping>~/out:=data</remapping>
              <frame_name>imu_frame</frame_name>
            </ros>
          </plugin>
          <pose>0 0 0.25 0 -0 0</pose>
        </sensor>
        <self_collide>0</self_collide>
        <enable_wind>0</enable_wind>
        <kinematic>0</kinematic>
      </link>
      <joint name='bl_caster_rotation_joint' type='revolute'>
        <pose relative_to='base_footprint'>-0.296 0.188 0.1565 0 -0 0</pose>
        <parent>base_footprint</parent>
        <child>bl_caster_rotation_link</child>
        <axis>
          <xyz>0 0 1</xyz>
          <limit>
            <lower>-1e+16</lower>
            <upper>1e+16</upper>
          </limit>
          <dynamics>
            <damping>0</damping>
            <friction>0</friction>
            <spring_reference>0</spring_reference>
            <spring_stiffness>0</spring_stiffness>
          </dynamics>
        </axis>
      </joint>
      <link name='bl_caster_rotation_link'>
        <pose relative_to='bl_caster_rotation_joint'>0 0 0 0 -0 0</pose>
        <inertial>
          <pose>0 0 -0.0425 0.418879 0 1.5708</pose>
          <mass>0.309754</mass>
          <inertia>
            <ixx>0.000584452</ixx>
            <ixy>0</ixy>
            <ixz>0</ixz>
            <iyy>0.000528726</iyy>
            <iyz>0</iyz>
            <izz>0.000179236</izz>
          </inertia>
        </inertial>
        <collision name='bl_caster_rotation_link_collision'>
          <pose>0 0 0 0 -0 0</pose>
          <geometry>
            <mesh>
              <scale>1 1 1</scale>
              <uri>model://mir_description/meshes/collision/caster_wheel_base.stl</uri>
            </mesh>
          </geometry>
          <surface>
            <contact>
              <ode/>
            </contact>
            <friction>
              <ode/>
              <torsional>
                <ode/>
              </torsional>
            </friction>
            <bounce/>
          </surface>
          <max_contacts>10</max_contacts>
        </collision>
        <visual name='bl_caster_rotation_link_visual'>
          <pose>0 0 0 0 -0 0</pose>
          <geometry>
            <mesh>
              <scale>1 1 1</scale>
              <uri>model://mir_description/meshes/visual/caster_wheel_base.stl</uri>
            </mesh>
          </geometry>
          <material>
            <script>
              <name>Gazebo/Grey</name>
              <uri>file://media/materials/scripts/gazebo.material</uri>
            </script>
          </material>
        </visual>
        <self_collide>0</self_collide>
        <enable_wind>0</enable_wind>
        <kinematic>0</kinematic>
      </link>
      <joint name='bl_caster_wheel_joint' type='revolute'>
        <pose relative_to='bl_caster_rotation_link'>-0.0382 0 -0.094 0 -0 0</pose>
        <parent>bl_caster_rotation_link</parent>
        <child>bl_caster_wheel_link</child>
        <axis>
          <xyz>0 1 0</xyz>
          <limit>
            <lower>-1e+16</lower>
            <upper>1e+16</upper>
          </limit>
          <dynamics>
            <spring_reference>0</spring_reference>
            <spring_stiffness>0</spring_stiffness>
          </dynamics>
        </axis>
      </joint>
      <link name='bl_caster_wheel_link'>
        <pose relative_to='bl_caster_wheel_joint'>0 0 0 0 -0 0</pose>
        <inertial>
          <pose>0 0 0 1.5708 -0 0</pose>
          <mass>1</mass>
          <inertia>
            <ixx>0.0010619</ixx>
            <ixy>0</ixy>
            <ixz>0</ixz>
            <iyy>0.0010619</iyy>
            <iyz>0</iyz>
            <izz>0.00195312</izz>
          </inertia>
        </inertial>
        <collision name='bl_caster_wheel_link_collision'>
          <pose>0 0 0 1.5708 -0 0</pose>
          <geometry>
            <cylinder>
              <length>1e-05</length>
              <radius>0.0625</radius>
            </cylinder>
          </geometry>
          <surface>
            <friction>
              <ode>
                <mu>1</mu>
                <mu2>1</mu2>
                <fdir1>0 0 1</fdir1>
                <slip1>0</slip1>
                <slip2>0.5</slip2>
              </ode>
              <torsional>
                <ode/>
              </torsional>
            </friction>
            <contact>
              <ode>
                <kp>1e+08</kp>
                <min_depth>0</min_depth>
              </ode>
            </contact>
            <bounce/>
          </surface>
          <max_contacts>10</max_contacts>
        </collision>
        <visual name='bl_caster_wheel_link_visual'>
          <pose>0 0 0 0 -0 0</pose>
          <geometry>
            <mesh>
              <scale>1 1 1</scale>
              <uri>model://mir_description/meshes/visual/wheel.stl</uri>
            </mesh>
          </geometry>
          <material>
            <script>
              <name>Gazebo/DarkGrey</name>
              <uri>file://media/materials/scripts/gazebo.material</uri>
            </script>
          </material>
        </visual>
        <self_collide>0</self_collide>
        <enable_wind>0</enable_wind>
        <kinematic>0</kinematic>
      </link>
      <joint name='br_caster_rotation_joint' type='revolute'>
        <pose relative_to='base_footprint'>-0.296 -0.188 0.1565 0 -0 0</pose>
        <parent>base_footprint</parent>
        <child>br_caster_rotation_link</child>
        <axis>
          <xyz>0 0 1</xyz>
          <limit>
            <lower>-1e+16</lower>
            <upper>1e+16</upper>
          </limit>
          <dynamics>
            <damping>0</damping>
            <friction>0</friction>
            <spring_reference>0</spring_reference>
            <spring_stiffness>0</spring_stiffness>
          </dynamics>
        </axis>
      </joint>
      <link name='br_caster_rotation_link'>
        <pose relative_to='br_caster_rotation_joint'>0 0 0 0 -0 0</pose>
        <inertial>
          <pose>0 0 -0.0425 0.418879 0 1.5708</pose>
          <mass>0.309754</mass>
          <inertia>
            <ixx>0.000584452</ixx>
            <ixy>0</ixy>
            <ixz>0</ixz>
            <iyy>0.000528726</iyy>
            <iyz>0</iyz>
            <izz>0.000179236</izz>
          </inertia>
        </inertial>
        <collision name='br_caster_rotation_link_collision'>
          <pose>0 0 0 0 -0 0</pose>
          <geometry>
            <mesh>
              <scale>1 1 1</scale>
              <uri>model://mir_description/meshes/collision/caster_wheel_base.stl</uri>
            </mesh>
          </geometry>
          <surface>
            <contact>
              <ode/>
            </contact>
            <friction>
              <ode/>
              <torsional>
                <ode/>
              </torsional>
            </friction>
            <bounce/>
          </surface>
          <max_contacts>10</max_contacts>
        </collision>
        <visual name='br_caster_rotation_link_visual'>
          <pose>0 0 0 0 -0 0</pose>
          <geometry>
            <mesh>
              <scale>1 1 1</scale>
              <uri>model://mir_description/meshes/visual/caster_wheel_base.stl</uri>
            </mesh>
          </geometry>
          <material>
            <script>
              <name>Gazebo/Grey</name>
              <uri>file://media/materials/scripts/gazebo.material</uri>
            </script>
          </material>
        </visual>
        <self_collide>0</self_collide>
        <enable_wind>0</enable_wind>
        <kinematic>0</kinematic>
      </link>
      <joint name='br_caster_wheel_joint' type='revolute'>
        <pose relative_to='br_caster_rotation_link'>-0.0382 0 -0.094 0 -0 0</pose>
        <parent>br_caster_rotation_link</parent>
        <child>br_caster_wheel_link</child>
        <axis>
          <xyz>0 1 0</xyz>
          <limit>
            <lower>-1e+16</lower>
            <upper>1e+16</upper>
          </limit>
          <dynamics>
            <spring_reference>0</spring_reference>
            <spring_stiffness>0</spring_stiffness>
          </dynamics>
        </axis>
      </joint>
      <link name='br_caster_wheel_link'>
        <pose relative_to='br_caster_wheel_joint'>0 0 0 0 -0 0</pose>
        <inertial>
          <pose>0 0 0 1.5708 -0 0</pose>
          <mass>1</mass>
          <inertia>
            <ixx>0.0010619</ixx>
            <ixy>0</ixy>
            <ixz>0</ixz>
            <iyy>0.0010619</iyy>
            <iyz>0</iyz>
            <izz>0.00195312</izz>
          </inertia>
        </inertial>
        <collision name='br_caster_wheel_link_collision'>
          <pose>0 0 0 1.5708 -0 0</pose>
          <geometry>
            <cylinder>
              <length>1e-05</length>
              <radius>0.0625</radius>
            </cylinder>
          </geometry>
          <surface>
            <friction>
              <ode>
                <mu>1</mu>
                <mu2>1</mu2>
                <fdir1>0 0 1</fdir1>
                <slip1>0</slip1>
                <slip2>0.5</slip2>
              </ode>
              <torsional>
                <ode/>
              </torsional>
            </friction>
            <contact>
              <ode>
                <kp>1e+08</kp>
                <min_depth>0</min_depth>
              </ode>
            </contact>
            <bounce/>
          </surface>
          <max_contacts>10</max_contacts>
        </collision>
        <visual name='br_caster_wheel_link_visual'>
          <pose>0 0 0 0 -0 0</pose>
          <geometry>
            <mesh>
              <scale>1 1 1</scale>
              <uri>model://mir_description/meshes/visual/wheel.stl</uri>
            </mesh>
          </geometry>
          <material>
            <script>
              <name>Gazebo/DarkGrey</name>
              <uri>file://media/materials/scripts/gazebo.material</uri>
            </script>
          </material>
        </visual>
        <self_collide>0</self_collide>
        <enable_wind>0</enable_wind>
        <kinematic>0</kinematic>
      </link>
      <joint name='fl_caster_rotation_joint' type='revolute'>
        <pose relative_to='base_footprint'>0.3037 0.188 0.1565 0 -0 0</pose>
        <parent>base_footprint</parent>
        <child>fl_caster_rotation_link</child>
        <axis>
          <xyz>0 0 1</xyz>
          <limit>
            <lower>-1e+16</lower>
            <upper>1e+16</upper>
          </limit>
          <dynamics>
            <damping>0</damping>
            <friction>0</friction>
            <spring_reference>0</spring_reference>
            <spring_stiffness>0</spring_stiffness>
          </dynamics>
        </axis>
      </joint>
      <link name='fl_caster_rotation_link'>
        <pose relative_to='fl_caster_rotation_joint'>0 0 0 0 -0 0</pose>
        <inertial>
          <pose>0 0 -0.0425 0.418879 0 1.5708</pose>
          <mass>0.309754</mass>
          <inertia>
            <ixx>0.000584452</ixx>
            <ixy>0</ixy>
            <ixz>0</ixz>
            <iyy>0.000528726</iyy>
            <iyz>0</iyz>
            <izz>0.000179236</izz>
          </inertia>
        </inertial>
        <collision name='fl_caster_rotation_link_collision'>
          <pose>0 0 0 0 -0 0</pose>
          <geometry>
            <mesh>
              <scale>1 1 1</scale>
              <uri>model://mir_description/meshes/collision/caster_wheel_base.stl</uri>
            </mesh>
          </geometry>
          <surface>
            <contact>
              <ode/>
            </contact>
            <friction>
              <ode/>
              <torsional>
                <ode/>
              </torsional>
            </friction>
            <bounce/>
          </surface>
          <max_contacts>10</max_contacts>
        </collision>
        <visual name='fl_caster_rotation_link_visual'>
          <pose>0 0 0 0 -0 0</pose>
          <geometry>
            <mesh>
              <scale>1 1 1</scale>
              <uri>model://mir_description/meshes/visual/caster_wheel_base.stl</uri>
            </mesh>
          </geometry>
          <material>
            <script>
              <name>Gazebo/Grey</name>
              <uri>file://media/materials/scripts/gazebo.material</uri>
            </script>
          </material>
        </visual>
        <self_collide>0</self_collide>
        <enable_wind>0</enable_wind>
        <kinematic>0</kinematic>
      </link>
      <joint name='fl_caster_wheel_joint' type='revolute'>
        <pose relative_to='fl_caster_rotation_link'>-0.0382 0 -0.094 0 -0 0</pose>
        <parent>fl_caster_rotation_link</parent>
        <child>fl_caster_wheel_link</child>
        <axis>
          <xyz>0 1 0</xyz>
          <limit>
            <lower>-1e+16</lower>
            <upper>1e+16</upper>
          </limit>
          <dynamics>
            <spring_reference>0</spring_reference>
            <spring_stiffness>0</spring_stiffness>
          </dynamics>
        </axis>
      </joint>
      <link name='fl_caster_wheel_link'>
        <pose relative_to='fl_caster_wheel_joint'>0 0 0 0 -0 0</pose>
        <inertial>
          <pose>0 0 0 1.5708 -0 0</pose>
          <mass>1</mass>
          <inertia>
            <ixx>0.0010619</ixx>
            <ixy>0</ixy>
            <ixz>0</ixz>
            <iyy>0.0010619</iyy>
            <iyz>0</iyz>
            <izz>0.00195312</izz>
          </inertia>
        </inertial>
        <collision name='fl_caster_wheel_link_collision'>
          <pose>0 0 0 1.5708 -0 0</pose>
          <geometry>
            <cylinder>
              <length>1e-05</length>
              <radius>0.0625</radius>
            </cylinder>
          </geometry>
          <surface>
            <friction>
              <ode>
                <mu>1</mu>
                <mu2>1</mu2>
                <fdir1>0 0 1</fdir1>
                <slip1>0</slip1>
                <slip2>0.5</slip2>
              </ode>
              <torsional>
                <ode/>
              </torsional>
            </friction>
            <contact>
              <ode>
                <kp>1e+08</kp>
                <min_depth>0</min_depth>
              </ode>
            </contact>
            <bounce/>
          </surface>
          <max_contacts>10</max_contacts>
        </collision>
        <visual name='fl_caster_wheel_link_visual'>
          <pose>0 0 0 0 -0 0</pose>
          <geometry>
            <mesh>
              <scale>1 1 1</scale>
              <uri>model://mir_description/meshes/visual/wheel.stl</uri>
            </mesh>
          </geometry>
          <material>
            <script>
              <name>Gazebo/DarkGrey</name>
              <uri>file://media/materials/scripts/gazebo.material</uri>
            </script>
          </material>
        </visual>
        <self_collide>0</self_collide>
        <enable_wind>0</enable_wind>
        <kinematic>0</kinematic>
      </link>
      <joint name='fr_caster_rotation_joint' type='revolute'>
        <pose relative_to='base_footprint'>0.3037 -0.188 0.1565 0 -0 0</pose>
        <parent>base_footprint</parent>
        <child>fr_caster_rotation_link</child>
        <axis>
          <xyz>0 0 1</xyz>
          <limit>
            <lower>-1e+16</lower>
            <upper>1e+16</upper>
          </limit>
          <dynamics>
            <damping>0</damping>
            <friction>0</friction>
            <spring_reference>0</spring_reference>
            <spring_stiffness>0</spring_stiffness>
          </dynamics>
        </axis>
      </joint>
      <link name='fr_caster_rotation_link'>
        <pose relative_to='fr_caster_rotation_joint'>0 0 0 0 -0 0</pose>
        <inertial>
          <pose>0 0 -0.0425 0.418879 0 1.5708</pose>
          <mass>0.309754</mass>
          <inertia>
            <ixx>0.000584452</ixx>
            <ixy>0</ixy>
            <ixz>0</ixz>
            <iyy>0.000528726</iyy>
            <iyz>0</iyz>
            <izz>0.000179236</izz>
          </inertia>
        </inertial>
        <collision name='fr_caster_rotation_link_collision'>
          <pose>0 0 0 0 -0 0</pose>
          <geometry>
            <mesh>
              <scale>1 1 1</scale>
              <uri>model://mir_description/meshes/collision/caster_wheel_base.stl</uri>
            </mesh>
          </geometry>
          <surface>
            <contact>
              <ode/>
            </contact>
            <friction>
              <ode/>
              <torsional>
                <ode/>
              </torsional>
            </friction>
            <bounce/>
          </surface>
          <max_contacts>10</max_contacts>
        </collision>
        <visual name='fr_caster_rotation_link_visual'>
          <pose>0 0 0 0 -0 0</pose>
          <geometry>
            <mesh>
              <scale>1 1 1</scale>
              <uri>model://mir_description/meshes/visual/caster_wheel_base.stl</uri>
            </mesh>
          </geometry>
          <material>
            <script>
              <name>Gazebo/Grey</name>
              <uri>file://media/materials/scripts/gazebo.material</uri>
            </script>
          </material>
        </visual>
        <self_collide>0</self_collide>
        <enable_wind>0</enable_wind>
        <kinematic>0</kinematic>
      </link>
      <joint name='fr_caster_wheel_joint' type='revolute'>
        <pose relative_to='fr_caster_rotation_link'>-0.0382 0 -0.094 0 -0 0</pose>
        <parent>fr_caster_rotation_link</parent>
        <child>fr_caster_wheel_link</child>
        <axis>
          <xyz>0 1 0</xyz>
          <limit>
            <lower>-1e+16</lower>
            <upper>1e+16</upper>
          </limit>
          <dynamics>
            <spring_reference>0</spring_reference>
            <spring_stiffness>0</spring_stiffness>
          </dynamics>
        </axis>
      </joint>
      <link name='fr_caster_wheel_link'>
        <pose relative_to='fr_caster_wheel_joint'>0 0 0 0 -0 0</pose>
        <inertial>
          <pose>0 0 0 1.5708 -0 0</pose>
          <mass>1</mass>
          <inertia>
            <ixx>0.0010619</ixx>
            <ixy>0</ixy>
            <ixz>0</ixz>
            <iyy>0.0010619</iyy>
            <iyz>0</iyz>
            <izz>0.00195312</izz>
          </inertia>
        </inertial>
        <collision name='fr_caster_wheel_link_collision'>
          <pose>0 0 0 1.5708 -0 0</pose>
          <geometry>
            <cylinder>
              <length>1e-05</length>
              <radius>0.0625</radius>
            </cylinder>
          </geometry>
          <surface>
            <friction>
              <ode>
                <mu>1</mu>
                <mu2>1</mu2>
                <fdir1>0 0 1</fdir1>
                <slip1>0</slip1>
                <slip2>0.5</slip2>
              </ode>
              <torsional>
                <ode/>
              </torsional>
            </friction>
            <contact>
              <ode>
                <kp>1e+08</kp>
                <min_depth>0</min_depth>
              </ode>
            </contact>
            <bounce/>
          </surface>
          <max_contacts>10</max_contacts>
        </collision>
        <visual name='fr_caster_wheel_link_visual'>
          <pose>0 0 0 0 -0 0</pose>
          <geometry>
            <mesh>
              <scale>1 1 1</scale>
              <uri>model://mir_description/meshes/visual/wheel.stl</uri>
            </mesh>
          </geometry>
          <material>
            <script>
              <name>Gazebo/DarkGrey</name>
              <uri>file://media/materials/scripts/gazebo.material</uri>
            </script>
          </material>
        </visual>
        <self_collide>0</self_collide>
        <enable_wind>0</enable_wind>
        <kinematic>0</kinematic>
      </link>
      <joint name='left_wheel_joint' type='revolute'>
        <pose relative_to='base_footprint'>0 0.2015 0.1 0 -0 0</pose>
        <parent>base_footprint</parent>
        <child>left_wheel_link</child>
        <axis>
          <xyz>0 1 0</xyz>
          <limit>
            <effort>250</effort>
            <velocity>20</velocity>
            <lower>-1e+16</lower>
            <upper>1e+16</upper>
          </limit>
          <dynamics>
            <spring_reference>0</spring_reference>
            <spring_stiffness>0</spring_stiffness>
          </dynamics>
        </axis>
      </joint>
      <link name='left_wheel_link'>
        <pose relative_to='left_wheel_joint'>0 0 0 0 -0 0</pose>
        <inertial>
          <pose>0 0 0 1.5708 -0 0</pose>
          <mass>1</mass>
          <inertia>
            <ixx>0.00262033</ixx>
            <ixy>0</ixy>
            <ixz>0</ixz>
            <iyy>0.00262033</iyy>
            <iyz>0</iyz>
            <izz>0.005</izz>
          </inertia>
        </inertial>
        <collision name='left_wheel_link_collision'>
          <pose>0 0 0 1.5708 -0 0</pose>
          <geometry>
            <cylinder>
              <length>0.038</length>
              <radius>0.1</radius>
            </cylinder>
          </geometry>
          <surface>
            <friction>
              <ode>
                <mu>300</mu>
                <mu2>300</mu2>
                <fdir1>0 0 1</fdir1>
              </ode>
              <torsional>
                <coefficient>300</coefficient>
                <use_patch_radius>0</use_patch_radius>
                <surface_radius>0.1</surface_radius>
                <ode/>
              </torsional>
            </friction>
            <contact>
              <ode>
                <min_depth>0.001</min_depth>
              </ode>
            </contact>
            <bounce/>
          </surface>
          <max_contacts>10</max_contacts>
        </collision>
        <visual name='left_wheel_link_visual'>
          <pose>0 0 0 1.5708 -0 0</pose>
          <geometry>
            <cylinder>
              <length>0.038</length>
              <radius>0.1</radius>
            </cylinder>
          </geometry>
          <material>
            <script>
              <name>Gazebo/DarkGrey</name>
              <uri>file://media/materials/scripts/gazebo.material</uri>
            </script>
          </material>
        </visual>
        <self_collide>0</self_collide>
        <enable_wind>0</enable_wind>
        <kinematic>0</kinematic>
      </link>
      <joint name='right_wheel_joint' type='revolute'>
        <pose relative_to='base_footprint'>0 -0.2015 0.1 0 -0 0</pose>
        <parent>base_footprint</parent>
        <child>right_wheel_link</child>
        <axis>
          <xyz>0 1 0</xyz>
          <limit>
            <effort>250</effort>
            <velocity>20</velocity>
            <lower>-1e+16</lower>
            <upper>1e+16</upper>
          </limit>
          <dynamics>
            <spring_reference>0</spring_reference>
            <spring_stiffness>0</spring_stiffness>
          </dynamics>
        </axis>
      </joint>
      <link name='right_wheel_link'>
        <pose relative_to='right_wheel_joint'>0 0 0 0 -0 0</pose>
        <inertial>
          <pose>0 0 0 1.5708 -0 0</pose>
          <mass>1</mass>
          <inertia>
            <ixx>0.00262033</ixx>
            <ixy>0</ixy>
            <ixz>0</ixz>
            <iyy>0.00262033</iyy>
            <iyz>0</iyz>
            <izz>0.005</izz>
          </inertia>
        </inertial>
        <collision name='right_wheel_link_collision'>
          <pose>0 0 0 1.5708 -0 0</pose>
          <geometry>
            <cylinder>
              <length>0.038</length>
              <radius>0.1</radius>
            </cylinder>
          </geometry>
          <surface>
            <friction>
              <ode>
                <mu>300</mu>
                <mu2>300</mu2>
                <fdir1>0 0 1</fdir1>
              </ode>
              <torsional>
                <coefficient>300</coefficient>
                <use_patch_radius>0</use_patch_radius>
                <surface_radius>0.1</surface_radius>
                <ode/>
              </torsional>
            </friction>
            <contact>
              <ode>
                <min_depth>0.001</min_depth>
              </ode>
            </contact>
            <bounce/>
          </surface>
          <max_contacts>10</max_contacts>
        </collision>
        <visual name='right_wheel_link_visual'>
          <pose>0 0 0 1.5708 -0 0</pose>
          <geometry>
            <cylinder>
              <length>0.038</length>
              <radius>0.1</radius>
            </cylinder>
          </geometry>
          <material>
            <script>
              <name>Gazebo/DarkGrey</name>
              <uri>file://media/materials/scripts/gazebo.material</uri>
            </script>
          </material>
        </visual>
        <self_collide>0</self_collide>
        <enable_wind>0</enable_wind>
        <kinematic>0</kinematic>
      </link>
      <joint name='ur_shoulder_pan_joint' type='revolute'>
        <pose relative_to='base_footprint'>0.135 0 0.9525 0 0 -1.5708</pose>
        <parent>base_footprint</parent>
        <child>ur_shoulder_link</child>
        <axis>
          <xyz>0 0 1</xyz>
          <limit>
            <lower>-6.28319</lower>
            <upper>6.28319</upper>
            <effort>150</effort>
            <velocity>3.14159</velocity>
          </limit>
          <dynamics>
            <damping>0</damping>
            <friction>0</friction>
            <spring_reference>0</spring_reference>
            <spring_stiffness>0</spring_stiffness>
          </dynamics>
        </axis>
      </joint>
      <link name='ur_shoulder_link'>
        <pose relative_to='ur_shoulder_pan_joint'>0 0 0 0 -0 0</pose>
        <inertial>
          <pose>0 0 0 0 -0 0</pose>
          <mass>0.01</mass>
          <inertia>
            <ixx>2.775e-05</ixx>
            <ixy>0</ixy>
            <ixz>0</ixz>
            <iyy>2.775e-05</iyy>
            <iyz>0</iyz>
            <izz>1.8e-05</izz>
          </inertia>
        </inertial>
        <collision name='ur_shoulder_link_collision'>
          <pose>0 0 0 0 -0 3.14159</pose>
          <geometry>
            <mesh>
              <scale>1 1 1</scale>
              <uri>file:///media/typlosion/shadow/work/ROS/ros_ws/install/ur_description/share/ur_description/meshes/ur5e/collision/shoulder.stl</uri>
            </mesh>
          </geometry>
          <max_contacts>10</max_contacts>
          <surface>
            <contact>
              <ode/>
            </contact>
            <bounce/>
            <friction>
              <torsional>
                <ode/>
              </torsional>
              <ode/>
            </friction>
          </surface>
        </collision>
        <visual name='ur_shoulder_link_visual'>
          <pose>0 0 0 0 -0 3.14159</pose>
          <geometry>
            <mesh>
              <scale>1 1 1</scale>
              <uri>file:///media/typlosion/shadow/work/ROS/ros_ws/install/ur_description/share/ur_description/meshes/ur5e/visual/shoulder.dae</uri>
            </mesh>
          </geometry>
        </visual>
        <self_collide>0</self_collide>
        <enable_wind>0</enable_wind>
        <kinematic>0</kinematic>
      </link>
      <joint name='ur_shoulder_lift_joint' type='revolute'>
        <pose relative_to='ur_shoulder_link'>0 0 0 1.5708 -0 0</pose>
        <parent>ur_shoulder_link</parent>
        <child>ur_upper_arm_link</child>
        <axis>
          <xyz>0 0 1</xyz>
          <limit>
            <lower>-6.28319</lower>
            <upper>6.28319</upper>
            <effort>150</effort>
            <velocity>3.14159</velocity>
          </limit>
          <dynamics>
            <damping>0</damping>
            <friction>0</friction>
            <spring_reference>0</spring_reference>
            <spring_stiffness>0</spring_stiffness>
          </dynamics>
        </axis>
      </joint>
      <link name='ur_upper_arm_link'>
        <pose relative_to='ur_shoulder_lift_joint'>0 0 0 0 -0 0</pose>
        <inertial>
          <pose>-0.2125 0 0.138 3.14159 1.57079 3.14159</pose>
          <mass>0.01</mass>
          <inertia>
            <ixx>0.000159521</ixx>
            <ixy>0</ixy>
            <ixz>0</ixz>
            <iyy>0.000159521</iyy>
            <iyz>0</iyz>
            <izz>1.8e-05</izz>
          </inertia>
        </inertial>
        <collision name='ur_upper_arm_link_collision'>
          <pose>0 0 0.138 1.5708 0 -1.5708</pose>
          <geometry>
            <mesh>
              <scale>1 1 1</scale>
              <uri>file:///media/typlosion/shadow/work/ROS/ros_ws/install/ur_description/share/ur_description/meshes/ur5e/collision/upperarm.stl</uri>
            </mesh>
          </geometry>
          <max_contacts>10</max_contacts>
          <surface>
            <contact>
              <ode/>
            </contact>
            <bounce/>
            <friction>
              <torsional>
                <ode/>
              </torsional>
              <ode/>
            </friction>
          </surface>
        </collision>
        <visual name='ur_upper_arm_link_visual'>
          <pose>0 0 0.138 1.5708 0 -1.5708</pose>
          <geometry>
            <mesh>
              <scale>1 1 1</scale>
              <uri>file:///media/typlosion/shadow/work/ROS/ros_ws/install/ur_description/share/ur_description/meshes/ur5e/visual/upperarm.dae</uri>
            </mesh>
          </geometry>
        </visual>
        <self_collide>0</self_collide>
        <enable_wind>0</enable_wind>
        <kinematic>0</kinematic>
      </link>
      <joint name='ur_elbow_joint' type='revolute'>
        <pose relative_to='ur_upper_arm_link'>-0.425 0 0 0 -0 0</pose>
        <parent>ur_upper_arm_link</parent>
        <child>ur_forearm_link</child>
        <axis>
          <xyz>0 0 1</xyz>
          <limit>
            <lower>-3.14159</lower>
            <upper>3.14159</upper>
            <effort>150</effort>
            <velocity>3.14159</velocity>
          </limit>
          <dynamics>
            <damping>0</damping>
            <friction>0</friction>
            <spring_reference>0</spring_reference>
            <spring_stiffness>0</spring_stiffness>
          </dynamics>
        </axis>
      </joint>
      <link name='ur_forearm_link'>
        <pose relative_to='ur_elbow_joint'>0 0 0 0 -0 0</pose>
        <inertial>
          <pose>-0.1961 0 0.007 3.14159 1.57079 3.14159</pose>
          <mass>0.01</mass>
          <inertia>
            <ixx>0.000137184</ixx>
            <ixy>0</ixy>
            <ixz>0</ixz>
            <iyy>0.000137184</iyy>
            <iyz>0</iyz>
            <izz>1.8e-05</izz>
          </inertia>
        </inertial>
        <collision name='ur_forearm_link_collision'>
          <pose>0 0 0.007 1.5708 0 -1.5708</pose>
          <geometry>
            <mesh>
              <scale>1 1 1</scale>
              <uri>file:///media/typlosion/shadow/work/ROS/ros_ws/install/ur_description/share/ur_description/meshes/ur5e/collision/forearm.stl</uri>
            </mesh>
          </geometry>
          <max_contacts>10</max_contacts>
          <surface>
            <contact>
              <ode/>
            </contact>
            <bounce/>
            <friction>
              <torsional>
                <ode/>
              </torsional>
              <ode/>
            </friction>
          </surface>
        </collision>
        <visual name='ur_forearm_link_visual'>
          <pose>0 0 0.007 1.5708 0 -1.5708</pose>
          <geometry>
            <mesh>
              <scale>1 1 1</scale>
              <uri>file:///media/typlosion/shadow/work/ROS/ros_ws/install/ur_description/share/ur_description/meshes/ur5e/visual/forearm.dae</uri>
            </mesh>
          </geometry>
        </visual>
        <self_collide>0</self_collide>
        <enable_wind>0</enable_wind>
        <kinematic>0</kinematic>
      </link>
      <joint name='ur_wrist_1_joint' type='revolute'>
        <pose relative_to='ur_forearm_link'>-0.3922 0 0.1333 0 -0 0</pose>
        <parent>ur_forearm_link</parent>
        <child>ur_wrist_1_link</child>
        <axis>
          <xyz>0 0 1</xyz>
          <limit>
            <lower>-6.28319</lower>
            <upper>6.28319</upper>
            <effort>28</effort>
            <velocity>3.14159</velocity>
          </limit>
          <dynamics>
            <damping>0</damping>
            <friction>0</friction>
            <spring_reference>0</spring_reference>
            <spring_stiffness>0</spring_stiffness>
          </dynamics>
        </axis>
      </joint>
      <link name='ur_wrist_1_link'>
        <pose relative_to='ur_wrist_1_joint'>0 0 0 0 -0 0</pose>
        <inertial>
          <pose>0 0 0 0 -0 0</pose>
          <mass>0.01</mass>
          <inertia>
            <ixx>2.1e-05</ixx>
            <ixy>0</ixy>
            <ixz>0</ixz>
            <iyy>2.1e-05</iyy>
            <iyz>0</iyz>
            <izz>1.8e-05</izz>
          </inertia>
        </inertial>
        <collision name='ur_wrist_1_link_collision'>
          <pose>0 0 -0.127 1.5708 -0 0</pose>
          <geometry>
            <mesh>
              <scale>1 1 1</scale>
              <uri>file:///media/typlosion/shadow/work/ROS/ros_ws/install/ur_description/share/ur_description/meshes/ur5e/collision/wrist1.stl</uri>
            </mesh>
          </geometry>
          <max_contacts>10</max_contacts>
          <surface>
            <contact>
              <ode/>
            </contact>
            <bounce/>
            <friction>
              <torsional>
                <ode/>
              </torsional>
              <ode/>
            </friction>
          </surface>
        </collision>
        <visual name='ur_wrist_1_link_visual'>
          <pose>0 0 -0.127 1.5708 -0 0</pose>
          <geometry>
            <mesh>
              <scale>1 1 1</scale>
              <uri>file:///media/typlosion/shadow/work/ROS/ros_ws/install/ur_description/share/ur_description/meshes/ur5e/visual/wrist1.dae</uri>
            </mesh>
          </geometry>
        </visual>
        <self_collide>0</self_collide>
        <enable_wind>0</enable_wind>
        <kinematic>0</kinematic>
      </link>
      <joint name='ur_wrist_2_joint' type='revolute'>
        <pose relative_to='ur_wrist_1_link'>0 -0.0997 -0 1.5708 -0 0</pose>
        <parent>ur_wrist_1_link</parent>
        <child>ur_wrist_2_link</child>
        <axis>
          <xyz>0 0 1</xyz>
          <limit>
            <lower>-6.28319</lower>
            <upper>6.28319</upper>
            <effort>28</effort>
            <velocity>3.14159</velocity>
          </limit>
          <dynamics>
            <damping>0</damping>
            <friction>0</friction>
            <spring_reference>0</spring_reference>
            <spring_stiffness>0</spring_stiffness>
          </dynamics>
        </axis>
      </joint>
      <link name='ur_wrist_2_link'>
        <pose relative_to='ur_wrist_2_joint'>0 0 0 0 -0 0</pose>
        <inertial>
          <pose>0 0 0 0 -0 0</pose>
          <mass>0.01</mass>
          <inertia>
            <ixx>2.1e-05</ixx>
            <ixy>0</ixy>
            <ixz>0</ixz>
            <iyy>2.1e-05</iyy>
            <iyz>0</iyz>
            <izz>1.8e-05</izz>
          </inertia>
        </inertial>
        <collision name='ur_wrist_2_link_collision'>
          <pose>0 0 -0.0997 0 -0 0</pose>
          <geometry>
            <mesh>
              <scale>1 1 1</scale>
              <uri>file:///media/typlosion/shadow/work/ROS/ros_ws/install/ur_description/share/ur_description/meshes/ur5e/collision/wrist2.stl</uri>
            </mesh>
          </geometry>
          <max_contacts>10</max_contacts>
          <surface>
            <contact>
              <ode/>
            </contact>
            <bounce/>
            <friction>
              <torsional>
                <ode/>
              </torsional>
              <ode/>
            </friction>
          </surface>
        </collision>
        <visual name='ur_wrist_2_link_visual'>
          <pose>0 0 -0.0997 0 -0 0</pose>
          <geometry>
            <mesh>
              <scale>1 1 1</scale>
              <uri>file:///media/typlosion/shadow/work/ROS/ros_ws/install/ur_description/share/ur_description/meshes/ur5e/visual/wrist2.dae</uri>
            </mesh>
          </geometry>
        </visual>
        <self_collide>0</self_collide>
        <enable_wind>0</enable_wind>
        <kinematic>0</kinematic>
      </link>
      <joint name='ur_wrist_3_joint' type='revolute'>
        <pose relative_to='ur_wrist_2_link'>0 0.0996 -0 -1.5708 0 0</pose>
        <parent>ur_wrist_2_link</parent>
        <child>ur_wrist_3_link</child>
        <axis>
          <xyz>0 0 1</xyz>
          <limit>
            <lower>-6.28319</lower>
            <upper>6.28319</upper>
            <effort>28</effort>
            <velocity>3.14159</velocity>
          </limit>
          <dynamics>
            <damping>0</damping>
            <friction>0</friction>
            <spring_reference>0</spring_reference>
            <spring_stiffness>0</spring_stiffness>
          </dynamics>
        </axis>
      </joint>
      <link name='ur_wrist_3_link'>
        <pose relative_to='ur_wrist_3_joint'>0 0 0 0 -0 0</pose>
        <inertial>
          <pose>-0.015366 -0.064537 0.024076 0 -0 0</pose>
          <mass>0.082</mass>
          <inertia>
            <ixx>0.00057677</ixx>
            <ixy>-1.12939e-05</ixy>
            <ixz>8.22073e-06</ixz>
            <iyy>3.69639e-05</iyy>
            <iyz>3.45271e-05</iyz>
            <izz>6.10359e-05</izz>
          </inertia>
        </inertial>
        <collision name='ur_wrist_3_link_collision'>
          <pose>0 0 -0.0989 1.5708 -0 0</pose>
          <geometry>
            <mesh>
              <scale>1 1 1</scale>
              <uri>file:///media/typlosion/shadow/work/ROS/ros_ws/install/ur_description/share/ur_description/meshes/ur5e/collision/wrist3.stl</uri>
            </mesh>
          </geometry>
          <max_contacts>10</max_contacts>
          <surface>
            <contact>
              <ode/>
            </contact>
            <bounce/>
            <friction>
              <torsional>
                <ode/>
              </torsional>
              <ode/>
            </friction>
          </surface>
        </collision>
        <collision name='ur_wrist_3_link_fixed_joint_lump__camera_mount_collision_1'>
          <pose>0.05 0.03 0.035 -1.5708 -0 -3.14159</pose>
          <geometry>
            <mesh>
              <scale>0.001 0.001 0.001</scale>
              <uri>model://mir_description/meshes/collision/D435i_mounted.STL</uri>
            </mesh>
          </geometry>
          <max_contacts>10</max_contacts>
          <surface>
            <contact>
              <ode/>
            </contact>
            <bounce/>
            <friction>
              <torsional>
                <ode/>
              </torsional>
              <ode/>
            </friction>
          </surface>
        </collision>
        <collision name='ur_wrist_3_link_fixed_joint_lump__realsense_link_collision_2'>
          <pose>0 -0.0735 0.0306 -1.57079 -1.57079 3.14159</pose>
          <geometry>
            <box>
              <size>0.02505 0.09 0.025</size>
            </box>
          </geometry>
          <surface>
            <contact>
              <ode>
                <kp>1e+13</kp>
                <kd>1</kd>
              </ode>
            </contact>
            <friction>
              <ode>
                <mu2>1</mu2>
                <fdir1>0 0 0</fdir1>
              </ode>
              <torsional>
                <ode/>
              </torsional>
            </friction>
            <bounce/>
          </surface>
          <max_contacts>10</max_contacts>
        </collision>
        <visual name='ur_wrist_3_link_visual'>
          <pose>0 0 -0.0989 1.5708 -0 0</pose>
          <geometry>
            <mesh>
              <scale>1 1 1</scale>
              <uri>file:///media/typlosion/shadow/work/ROS/ros_ws/install/ur_description/share/ur_description/meshes/ur5e/visual/wrist3.dae</uri>
            </mesh>
          </geometry>
        </visual>
        <visual name='ur_wrist_3_link_fixed_joint_lump__camera_mount_visual_1'>
          <pose>0.05 0.03 0.035 -1.5708 -0 -3.14159</pose>
          <geometry>
            <mesh>
              <scale>0.001 0.001 0.001</scale>
              <uri>model://mir_description/meshes/visual/D435i_mounted.STL</uri>
            </mesh>
          </geometry>
        </visual>
        <visual name='ur_wrist_3_link_fixed_joint_lump__realsense_link_visual_2'>
          <pose>0 -0.0735 0.0349 -0 -0 -3.14159</pose>
          <geometry>
            <mesh>
              <scale>1 1 1</scale>
              <uri>file:///media/typlosion/shadow/work/ROS/ros_ws/install/realsense2_description/share/realsense2_description/meshes/d435.dae</uri>
            </mesh>
          </geometry>
        </visual>
        <self_collide>0</self_collide>
        <enable_wind>0</enable_wind>
        <kinematic>0</kinematic>
        <sensor name='realsensecolor' type='camera'>
          <camera name='realsense'>
            <horizontal_fov>1.21126</horizontal_fov>
            <image>
              <width>1920</width>
              <height>1080</height>
              <format>RGB_INT8</format>
            </image>
            <clip>
              <near>0.1</near>
              <far>100</far>
            </clip>
            <noise>
              <type>gaussian</type>
              <mean>0</mean>
              <stddev>0.007</stddev>
            </noise>
          </camera>
          <always_on>1</always_on>
          <update_rate>30</update_rate>
          <visualize>1</visualize>
          <pose>-0.0175 -0.0735 0.0306 -3.14159 -1.57079 -1.57079</pose>
        </sensor>
        <sensor name='realsenseired1' type='camera'>
          <camera name='realsense'>
            <horizontal_fov>1.48702</horizontal_fov>
            <image>
              <width>848</width>
              <height>480</height>
              <format>L_INT8</format>
            </image>
            <clip>
              <near>0.1</near>
              <far>100</far>
            </clip>
            <noise>
              <type>gaussian</type>
              <mean>0</mean>
              <stddev>0.05</stddev>
            </noise>
          </camera>
          <always_on>1</always_on>
          <update_rate>60</update_rate>
          <visualize>0</visualize>
          <pose>-0.0175 -0.0735 0.0306 -3.14159 -1.57079 -1.57079</pose>
        </sensor>
        <sensor name='realsenseired2' type='camera'>
          <camera name='realsense'>
            <horizontal_fov>1.48702</horizontal_fov>
            <image>
              <width>848</width>
              <height>480</height>
              <format>L_INT8</format>
            </image>
            <clip>
              <near>0.1</near>
              <far>100</far>
            </clip>
            <noise>
              <type>gaussian</type>
              <mean>0</mean>
              <stddev>0.05</stddev>
            </noise>
          </camera>
          <always_on>1</always_on>
          <update_rate>60</update_rate>
          <visualize>0</visualize>
          <pose>-0.0175 -0.0735 0.0306 -3.14159 -1.57079 -1.57079</pose>
        </sensor>
        <sensor name='realsensedepth' type='depth'>
          <camera name='realsense'>
            <horizontal_fov>1.48702</horizontal_fov>
            <image>
              <width>848</width>
              <height>480</height>
            </image>
            <clip>
              <near>0.1</near>
              <far>100</far>
            </clip>
            <noise>
              <type>gaussian</type>
              <mean>0</mean>
              <stddev>0.1</stddev>
            </noise>
          </camera>
          <always_on>1</always_on>
          <update_rate>60</update_rate>
          <visualize>0</visualize>
          <pose>-0.0175 -0.0735 0.0306 -3.14159 -1.57079 -1.57079</pose>
        </sensor>
        <sensor name='realsenseimu' type='imu'>
          <always_on>1</always_on>
          <update_rate>200</update_rate>
          <topic>__default_topic__</topic>
          <plugin name='realsenseimu' filename='libgazebo_ros_imu_sensor.so'>
            <ros>
              <namespace>/camera</namespace>
              <remapping>~/out:=imu</remapping>
            </ros>
            <bodyName>realsense_link</bodyName>
            <frameName>realsense_gyro_optical_frame</frameName>
            <updateRateHZ>200</updateRateHZ>
            <gaussianNoise>0.1</gaussianNoise>
            <xyzOffset>0 0 0</xyzOffset>
            <rpyOffset>0 0 0</rpyOffset>
          </plugin>
          <pose>-0.0175 -0.0735 0.0306 -3.14159 -1.57079 -1.57079</pose>
          <imu/>
        </sensor>
      </link>
      <plugin name='gazebo_ros2_control_ur' filename='libgazebo_ros2_control.so'/>
      <plugin name='camera' filename='librealsense_gazebo_plugin.so'>
        <prefix>realsense</prefix>
        <colorUpdateRate>30</colorUpdateRate>
        <colorTopicName>camera/color/image_raw</colorTopicName>
        <colorOpticalframeName>realsense_color_optical_frame</colorOpticalframeName>
        <colorCameraInfoTopicName>color/camera_info</colorCameraInfoTopicName>
        <infraredUpdateRate>60</infraredUpdateRate>
        <infrared1TopicName>camera/infra1/image_rect_raw</infrared1TopicName>
        <infrared2TopicName>camera/infra2/image_rect_raw</infrared2TopicName>
        <infrared1CameraInfoTopicName>camera/infra1/camera_info</infrared1CameraInfoTopicName>
        <infrared2CameraInfoTopicName>camera/infra2/camera_info</infrared2CameraInfoTopicName>
        <infrared1OpticalframeName>realsense_left_ir_optical_frame</infrared1OpticalframeName>
        <infrared2OpticalframeName>realsense_right_ir_optical_frame</infrared2OpticalframeName>
        <rangeMinDepth>0.2</rangeMinDepth>
        <rangeMaxDepth>10.0</rangeMaxDepth>
        <depthUpdateRate>60</depthUpdateRate>
        <depthTopicName>camera/depth/image_rect_raw</depthTopicName>
        <depthCameraInfoTopicName>camera/depth/camera_info</depthCameraInfoTopicName>
        <depthOpticalframeName>realsense_depth_optical_frame</depthOpticalframeName>
        <pointCloud>1</pointCloud>
        <pointCloudTopicName>depth/color/points</pointCloudTopicName>
        <pointCloudCutoff>0.5</pointCloudCutoff>
      </plugin>
      <static>0</static>
      <plugin name='gazebo_ros2_control' filename='libgazebo_ros2_control.so'>
        <parameters>/media/typlosion/shadow/work/ROS/ros_ws/install/mir_description/share/mir_description/config/diffdrive_controller.yaml</parameters>
      </plugin>
      <pose>0 0 0 0 -0 0</pose>
    </model>
    <model name='marker_0001'>
      <static>1</static>
      <link name='link'>
        <visual name='visual'>
          <geometry>
            <mesh>
              <uri>model://marker_0001/meshes/marker_0001.dae</uri>
              <scale>2 2 2</scale>
            </mesh>
          </geometry>
        </visual>
        <self_collide>0</self_collide>
        <enable_wind>0</enable_wind>
        <kinematic>0</kinematic>
      </link>
      <pose>9.0744 0.153091 0 0 -0 0</pose>
    </model>
    <state world_name='maze_world'>
      <sim_time>1589 876000000</sim_time>
      <real_time>675 873782043</real_time>
      <wall_time>1711964057 413177102</wall_time>
      <iterations>536245</iterations>
      <model name='ground_plane'>
        <pose>0 0 0 0 -0 0</pose>
        <scale>1 1 1</scale>
        <link name='link'>
          <pose>0 0 0 0 -0 0</pose>
          <velocity>0 0 0 0 -0 0</velocity>
          <acceleration>0 0 0 0 -0 0</acceleration>
          <wrench>0 0 0 0 -0 0</wrench>
        </link>
      </model>
      <model name='marker_0001'>
        <pose>6.97204 -1.38111 0.056322 2.51412 -1.54916 0.619947</pose>
        <scale>1 1 1</scale>
        <link name='link'>
          <pose>6.97204 -1.38111 0.056322 2.51412 -1.54916 0.619947</pose>
          <velocity>0 0 0 0 -0 0</velocity>
          <acceleration>0 0 0 0 -0 0</acceleration>
          <wrench>0 0 0 0 -0 0</wrench>
        </link>
      </model>
      <model name='maze'>
        <pose>-0.078283 0.099 0 0 -0 0</pose>
        <scale>1 1 1</scale>
        <link name='Wall_0'>
          <pose>-0.047747 10.024 0 0 -0 0</pose>
          <velocity>0 0 0 0 -0 0</velocity>
          <acceleration>0 0 0 0 -0 0</acceleration>
          <wrench>0 0 0 0 -0 0</wrench>
        </link>
        <link name='Wall_1'>
          <pose>9.87726 0.098984 0 0 0 -1.5708</pose>
          <velocity>0 0 0 0 -0 0</velocity>
          <acceleration>0 0 0 0 -0 0</acceleration>
          <wrench>0 0 0 0 -0 0</wrench>
        </link>
        <link name='Wall_2'>
          <pose>-0.047747 -9.82602 0 0 -0 3.14159</pose>
          <velocity>0 0 0 0 -0 0</velocity>
          <acceleration>0 0 0 0 -0 0</acceleration>
          <wrench>0 0 0 0 -0 0</wrench>
        </link>
        <link name='Wall_24'>
          <pose>5.27261 3.31804 0 0 -0 3.14159</pose>
          <velocity>0 0 0 0 -0 0</velocity>
          <acceleration>0 0 0 0 -0 0</acceleration>
          <wrench>0 0 0 0 -0 0</wrench>
        </link>
        <link name='Wall_25'>
          <pose>4.59761 5.86804 0 0 -0 1.5708</pose>
          <velocity>0 0 0 0 -0 0</velocity>
          <acceleration>0 0 0 0 -0 0</acceleration>
          <wrench>0 0 0 0 -0 0</wrench>
        </link>
        <link name='Wall_27'>
          <pose>7.03086 4.83352 0 0 0 -1.5708</pose>
          <velocity>0 0 0 0 -0 0</velocity>
          <acceleration>0 0 0 0 -0 0</acceleration>
          <wrench>0 0 0 0 -0 0</wrench>
        </link>
        <link name='Wall_28'>
          <pose>8.45586 2.15852 0 0 -0 0</pose>
          <velocity>0 0 0 0 -0 0</velocity>
          <acceleration>0 0 0 0 -0 0</acceleration>
          <wrench>0 0 0 0 -0 0</wrench>
        </link>
        <link name='Wall_3'>
          <pose>-9.97274 0.098984 0 0 -0 1.5708</pose>
          <velocity>0 0 0 0 -0 0</velocity>
          <acceleration>0 0 0 0 -0 0</acceleration>
          <wrench>0 0 0 0 -0 0</wrench>
        </link>
        <link name='Wall_30'>
          <pose>-4.43742 -2.72991 0 0 0 -1.5708</pose>
          <velocity>0 0 0 0 -0 0</velocity>
          <acceleration>0 0 0 0 -0 0</acceleration>
          <wrench>0 0 0 0 -0 0</wrench>
        </link>
        <link name='Wall_31'>
          <pose>-7.23742 -5.40491 0 0 -0 3.14159</pose>
          <velocity>0 0 0 0 -0 0</velocity>
          <acceleration>0 0 0 0 -0 0</acceleration>
          <wrench>0 0 0 0 -0 0</wrench>
        </link>
        <link name='Wall_5'>
          <pose>-1.97739 1.96804 0 0 -0 0</pose>
          <velocity>0 0 0 0 -0 0</velocity>
          <acceleration>0 0 0 0 -0 0</acceleration>
          <wrench>0 0 0 0 -0 0</wrench>
        </link>
        <link name='Wall_6'>
          <pose>5.94761 2.64304 0 0 -0 1.5708</pose>
          <velocity>0 0 0 0 -0 0</velocity>
          <acceleration>0 0 0 0 -0 0</acceleration>
          <wrench>0 0 0 0 -0 0</wrench>
        </link>
        <link name='Wall_8'>
          <pose>5.94761 3.31804 0 0 -0 0</pose>
          <velocity>0 0 0 0 -0 0</velocity>
          <acceleration>0 0 0 0 -0 0</acceleration>
          <wrench>0 0 0 0 -0 0</wrench>
        </link>
      </model>
      <model name='mir_robot'>
        <pose>0.274453 -0.146224 -2.2e-05 -8e-06 -3.4e-05 -0.008723</pose>
        <scale>1 1 1</scale>
        <link name='base_footprint'>
          <pose>0.274453 -0.146224 -2.2e-05 -8e-06 -3.4e-05 -0.008723</pose>
          <velocity>0.000147 0.000629 0.000251 0.001044 -0.000677 0.000341</velocity>
          <acceleration>-0.021766 -0.103193 0.880987 1.18118 -0.417281 0.135378</acceleration>
          <wrench>-3.58508 -16.9969 145.107 0 -0 0</wrench>
        </link>
        <link name='bl_caster_rotation_link'>
          <pose>-0.019902 0.044353 0.156488 -3.7e-05 0.000433 -0.465514</pose>
          <velocity>-4.7e-05 0.000333 9.7e-05 -0.001766 -0.003193 0.006929</velocity>
          <acceleration>0.735895 0.185623 0.432693 -1.22787 -1.00888 0.702867</acceleration>
          <wrench>0.227946 0.057497 0.134029 0 -0 0</wrench>
        </link>
        <link name='bl_caster_wheel_link'>
          <pose>-0.054049 0.061502 0.0625 -3.14151 -1.07746 2.67601</pose>
          <velocity>-3.2e-05 4.8e-05 -9e-06 -0.000196 0.00061 0.00719</velocity>
          <acceleration>0.015873 -0.72389 0.129355 -2.71459 -0.765388 0.128202</acceleration>
          <wrench>0.015873 -0.72389 0.129355 0 -0 0</wrench>
        </link>
        <link name='br_caster_rotation_link'>
          <pose>-0.023179 -0.331633 0.156488 3.4e-05 0.000418 -2.9041</pose>
          <velocity>0.000148 0.000346 -9.6e-05 6.6e-05 -0.002053 -0.006324</velocity>
          <acceleration>-0.34082 0.260435 0.101241 -0.712392 -0.006493 -0.471304</acceleration>
          <wrench>-0.10557 0.080671 0.03136 0 -0 0</wrench>
        </link>
        <link name='br_caster_wheel_link'>
          <pose>0.013963 -0.322646 0.0625 3.14155 -0.393395 0.237504</pose>
          <velocity>0.000316 0.000118 -3e-05 -0.00055 -0.000451 -0.006509</velocity>
          <acceleration>0.057556 -0.460525 -0.091806 -2.10298 0.555443 1.84507</acceleration>
          <wrench>0.057556 -0.460525 -0.091806 0 -0 0</wrench>
        </link>
        <link name='fl_caster_rotation_link'>
          <pose>0.579775 0.039122 0.156495 -2.8e-05 0.000162 -0.988679</pose>
          <velocity>-7.7e-05 0.000549 0.000227 -0.007228 -0.005074 0.007682</velocity>
          <acceleration>0.917565 -0.198835 0.530733 -1.59637 -1.34113 -0.402619</acceleration>
          <wrench>0.284219 -0.06159 0.164397 0 -0 0</wrench>
        </link>
        <link name='fl_caster_wheel_link'>
          <pose>0.558769 0.071032 0.0625 -4.1e-05 0.742685 -0.988703</pose>
          <velocity>-0.000124 0.000205 -1.7e-05 0.001048 0.000869 0.008066</velocity>
          <acceleration>-0.410768 -0.752882 0.151994 2.14899 1.39879 -2.96074</acceleration>
          <wrench>-0.410768 -0.752882 0.151994 0 -0 0</wrench>
        </link>
        <link name='fr_caster_rotation_link'>
          <pose>0.576495 -0.336864 0.156497 -1e-05 0.000121 -1.20767</pose>
          <velocity>5.2e-05 0.000598 4.6e-05 -0.003194 -0.001125 0.00659</velocity>
          <acceleration>0.38697 -0.292139 0.209258 1.76011 0.525439 1.86152</acceleration>
          <wrench>0.119865 -0.090491 0.064818 0 -0 0</wrench>
        </link>
        <link name='fr_caster_wheel_link'>
          <pose>0.562925 -0.301153 0.0625 -3.7e-05 1.23605 -1.2077</pose>
          <velocity>-0.000155 0.000468 -3.7e-05 0.001122 0.000793 0.006844</velocity>
          <acceleration>-0.199784 -0.266315 -0.063778 2.11694 -1.27065 -0.477055</acceleration>
          <wrench>-0.199784 -0.266315 -0.063778 0 -0 0</wrench>
        </link>
        <link name='left_wheel_link'>
          <pose>0.276208 0.055264 0.099993 -9.4e-05 0.496442 -0.008768</pose>
          <velocity>1.1e-05 0.000432 0.000949 -0.004312 9.8e-05 0.000282</velocity>
          <acceleration>-0.003737 -0.063357 1.61768 2.10069 0.379553 0.075926</acceleration>
          <wrench>-0.003737 -0.063357 1.61768 0 -0 0</wrench>
        </link>
        <link name='right_wheel_link'>
          <pose>0.272692 -0.347708 0.1 0.000132 0.501085 -0.00866</pose>
          <velocity>0.00015 0.000417 0.000311 -0.005106 0.001572 0.000351</velocity>
          <acceleration>0.051781 -0.077805 0.927672 -1.84637 1.28507 -2.99731</acceleration>
          <wrench>0.051781 -0.077805 0.927672 0 -0 0</wrench>
        </link>
        <link name='ur_forearm_link'>
          <pose>0.409713 -0.147367 1.37747 1.63729 1.57007 -3.08309</pose>
          <velocity>0.001539 9.4e-05 0.000137 -0.00062 -0.013951 0.008605</velocity>
          <acceleration>-0.92293 -0.50045 0.743164 -0.023451 -1.11739 1.16834</acceleration>
          <wrench>-0.009229 -0.005005 0.007432 0 -0 0</wrench>
        </link>
        <link name='ur_shoulder_link'>
          <pose>0.409416 -0.147394 0.952483 -1.7e-05 3.4e-05 3.1336</pose>
          <velocity>-0.000501 -0.000327 0.000356 0.001907 -0.000689 0.008627</velocity>
          <acceleration>-0.332253 -0.962354 0.96353 2.03908 -0.424927 2.13699</acceleration>
          <wrench>-0.003323 -0.009624 0.009635 0 -0 0</wrench>
        </link>
        <link name='ur_upper_arm_link'>
          <pose>0.409415 -0.147396 0.952479 1.6648 1.57009 -3.05559</pose>
          <velocity>-0.000511 -0.000342 0.000244 -0.000712 0.004838 0.008611</velocity>
          <acceleration>-0.417855 -0.844088 0.765151 -0.019058 -1.17637 -0.912366</acceleration>
          <wrench>-0.004179 -0.008441 0.007652 0 -0 0</wrench>
        </link>
        <link name='ur_wrist_1_link'>
          <pose>0.411065 -0.014054 1.76966 -1.57087 0.26319 -0.00801</pose>
          <velocity>-0.005084 0.000358 -2.9e-05 -0.000764 0.041419 0.008683</velocity>
          <acceleration>-4.67209 -0.385834 0.595673 2.56474 -1.50474 -2.16003</acceleration>
          <wrench>-0.046721 -0.003858 0.005957 0 -0 0</wrench>
        </link>
        <link name='ur_wrist_2_link'>
          <pose>0.437 -0.014255 1.86593 -0.263191 0.000139 -1.57804</pose>
          <velocity>-0.001146 0.000669 -0.001136 -0.01111 0.041485 -0.029182</velocity>
          <acceleration>-0.70833 -0.092421 -0.518573 -2.73508 -0.917703 -1.30294</acceleration>
          <wrench>-0.007083 -0.000924 -0.005186 0 -0 0</wrench>
        </link>
        <link name='ur_wrist_3_link'>
          <pose>0.533168 -0.014948 1.84001 -1.834 6.6e-05 -1.57802</pose>
          <velocity>-0.002256 -0.002424 -0.00528 -0.067659 0.042319 -0.013918</velocity>
          <acceleration>0.774278 0.015938 -7.41567 1.11932 1.13767 1.88791</acceleration>
          <wrench>0.063491 0.001307 -0.608085 0 -0 0</wrench>
        </link>
      </model>
      <light name='sun'>
        <pose>0 0 10 0 -0 0</pose>
      </light>
    </state>
    <gui fullscreen='0'>
      <camera name='user_camera'>
        <pose>5.42526 -4.61873 2.23824 0 0.387643 0.992194</pose>
        <view_controller>orbit</view_controller>
        <projection_type>perspective</projection_type>
      </camera>
    </gui>
  </world>
</sdf>
